<?xml version="1.0"?>

<robot name="differential_drive_robot"
       xmlns:xacro="http://www.ros.org/wiki/xacro">

    <!-- PARAMETERS -->

    <xacro:property name="body_link_x_dim" value="1.0"/>
    <xacro:property name="body_link_y_dim" value="0.6"/>
    <xacro:property name="body_link_z_dim" value="0.2"/>

    <xacro:property name="wheel_link_radius" value="0.15"/>
    <xacro:property name="wheel_link_length" value="0.1"/>
    <xacro:property name="wheel_link_z_location" value="-0.1"/>

    <xacro:property name="body_density" value="2710.0"/>
    <xacro:property name="wheel_density" value="2710.0"/>

    <xacro:property name="pi_const" value="3.14159265"/>

    <!-- MASS -->

    <xacro:property
        name="body_mass"
        value="${body_density * body_link_x_dim * body_link_y_dim * body_link_z_dim}"/>

    <xacro:property
        name="wheel_mass"
        value="${wheel_density * pi_const * wheel_link_radius * wheel_link_radius * wheel_link_length}"/>

    <!-- WHEEL INERTIA -->

    <xacro:property
        name="Iz_wheel"
        value="${0.5 * wheel_mass * wheel_link_radius * wheel_link_radius}"/>

    <xacro:property
        name="I_wheel"
        value="${(1.0/12.0) * wheel_mass * (3.0 * wheel_link_radius * wheel_link_radius + wheel_link_length * wheel_link_length)}"/>

    <!-- GAZEBO INCLUDE -->

    <xacro:include filename="$(find mobile_robot)/model/robot.gazebo"/>

    <!-- WHEEL INERTIA MACRO -->

    <xacro:macro name="inertial_wheel">

        <inertial>

            <origin xyz="0 0 0" rpy="0 0 0"/>

            <mass value="${wheel_mass}"/>

            <inertia
                ixx="${I_wheel}"
                ixy="0.0"
                ixz="0.0"
                iyy="${I_wheel}"
                iyz="0.0"
                izz="${Iz_wheel}"/>

        </inertial>

    </xacro:macro>

    <!-- DUMMY LINK -->

    <link name="dummy"/>

    <joint name="dummy_joint" type="fixed">

        <parent link="dummy"/>
        <child link="body_link"/>

    </joint>

    <!-- BODY LINK -->

    <link name="body_link">

        <visual>
            <geometry>
                <box size="${body_link_x_dim}
                           ${body_link_y_dim}
                           ${body_link_z_dim}"/>
            </geometry>
        </visual>

        <collision>

            <origin xyz="0 0 0" rpy="0 0 0"/>

            <geometry>
                <box size="${body_link_x_dim}
                           ${body_link_y_dim}
                           ${body_link_z_dim}"/>
            </geometry>

        </collision>

        <inertial>

            <origin xyz="0 0 0" rpy="0 0 0"/>

            <mass value="${body_mass}"/>

            <inertia
                ixx="${(1.0/12.0)*body_mass*(body_link_y_dim*body_link_y_dim + body_link_z_dim*body_link_z_dim)}"
                ixy="0.0"
                ixz="0.0"
                iyy="${(1.0/12.0)*body_mass*(body_link_x_dim*body_link_x_dim + body_link_z_dim*body_link_z_dim)}"
                iyz="0.0"
                izz="${(1.0/12.0)*body_mass*(body_link_x_dim*body_link_x_dim + body_link_y_dim*body_link_y_dim)}"/>

        </inertial>

    </link>

    <!-- WHEEL MACRO -->

    <xacro:macro name="wheel" params="name x y">

        <joint name="${name}_joint" type="continuous">

            <parent link="body_link"/>
            <child link="${name}_link"/>

            <origin xyz="${x} ${y} ${wheel_link_z_location}"
                    rpy="0 0 0"/>

            <axis xyz="0 1 0"/>

            <limit effort="1000" velocity="1000"/>

            <dynamics damping="1.0"
                      friction="1.0"/>

        </joint>

        <link name="${name}_link">

            <visual>

                <origin xyz="0 0 0"
                        rpy="1.570795 0 0"/>

                <geometry>
                    <cylinder length="${wheel_link_length}"
                              radius="${wheel_link_radius}"/>
                </geometry>

            </visual>

            <collision>

                <origin xyz="0 0 0"
                        rpy="1.570795 0 0"/>

                <geometry>
                    <cylinder length="${wheel_link_length}"
                              radius="${wheel_link_radius}"/>
                </geometry>

            </collision>

            <xacro:inertial_wheel/>

        </link>

    </xacro:macro>

    <!-- FOUR WHEELS -->

    <xacro:wheel
        name="wheel1"
        x="0.35"
        y="-0.35"/>

    <xacro:wheel
        name="wheel2"
        x="0.35"
        y="0.35"/>

    <xacro:wheel
        name="wheel3"
        x="-0.35"
        y="-0.35"/>

    <xacro:wheel
        name="wheel4"
        x="-0.35"
        y="0.35"/>

</robot>